<?xml version="1.0"?>

<robot xmlns:xacro="http://www.ros.org/wiki/xacro">

    <xacro:include filename="$(find lite2_description)/xacro/imu_link.xacro"/>

    <link name="TORSO">
      <visual>
        <origin rpy="-1.570796 3.1415926 3.1415926" xyz="0 0 0"/>
        <geometry>
          <mesh filename="package://lite2_description/meshes/TORSO2.dae" />
        </geometry>
      </visual>
      <collision>
        <geometry>
          <!-- <box size="0.234 0.184 0.08"/> -->
          <box size="0.234 0.184 0.1"/>
        </geometry>
      </collision>
    </link>

    <link name="INERTIA">
      <inertial>
        <origin xyz="0.046396 -0.0017592 0.028665" />
        <mass value="5.298" />
        <inertia ixx="0.0095569" ixy="5.9672E-05" ixz="9.3193E-05" iyy="0.014357" iyz="1.9063E-05" izz="0.01949" />
      </inertial>
    </link>

    <joint name="Torso2Inertia" type="fixed">
      <parent link="TORSO" />
      <child link="INERTIA" />
    </joint>

    <link name="FL_HIP">
      <inertial>
        <origin xyz="-0.0047 -0.0091 -0.0018" />
        <mass value="0.428" />
        <inertia ixx="0.00014538" ixy="8.1579E-07" ixz="-1.264E-05" iyy="0.00024024" iyz="1.3443E-06" izz="0.00013038" />
      </inertial>
      <visual>
        <geometry>
         <mesh filename="package://lite2_description/meshes/FL_HIP.dae" />
        </geometry>
      </visual>
    </link>

    <joint name="FL_HipX" type="revolute">
      <origin xyz="0.175 0.055 0" />
      <parent link="TORSO" />
      <child link="FL_HIP" />
      <axis xyz="1 0 0" />
      <limit lower="-0.523" upper="0.523" effort="13.2" velocity="20" />
    </joint>

    <link name="FL_THIGH">
      <inertial>
        <origin xyz="-0.00523 -0.0216 -0.0273" />
        <mass value="0.61" />
        <inertia ixx="0.001" ixy="-2.5E-06" ixz="-1.12E-04" iyy="0.00116" iyz="3.75E-07" izz="2.68E-04" />
      </inertial>
      <visual>
        <geometry>
          <mesh filename="package://lite2_description/meshes/L_THIGH.dae" />
        </geometry>
      </visual>
      <collision>
        <origin xyz="0 0 -0.06"/>
        <geometry>
          <box size="0.03 0.03 0.12"/>
        </geometry>
      </collision>
    </link>

    <joint name="FL_HipY" type="revolute">
      <origin xyz="0 0.081 0" />
      <parent link="FL_HIP" />
      <child link="FL_THIGH" />
      <axis xyz="0 -1 0" />
      <limit lower="-3.49" upper="0.349" effort="13.2" velocity="20" />
    </joint>

    <link name="FL_SHANK">
      <inertial>
        <origin xyz="0.00585 -8.732E-07 -0.12" />
        <mass value="0.145" />
        <inertia ixx="6.68E-04" ixy="-1.24E-08" ixz="6.91E-06" iyy="6.86E-04" iyz="5.65E-09" izz="3.155E-05" />
      </inertial>
      <visual>
        <geometry>
          <mesh filename="package://lite2_description/meshes/SHANK.dae" />
        </geometry>
      </visual>
      <collision>
        <!-- <origin xyz="0 0 -0.08"/> -->
        <origin xyz="0 0 -0.09"/>
        <geometry>
          <!-- <box size="0.02 0.02 0.16"/> -->
          <box size="0.02 0.02 0.18"/>
        </geometry>
      </collision>
    </link>

    <joint name="FL_Knee" type="revolute">
      <origin xyz="0 0 -0.18" />
      <parent link="FL_THIGH" />
      <child link="FL_SHANK" />
      <axis xyz="0 -1 0" />
      <limit lower="0.419" upper="2.53" effort="28" velocity="20" />
    </joint>

    <link name="FL_FOOT">
      <inertial>
        <mass value="1E-12" />
        <inertia ixx="1E-12" ixy="0" ixz="0" iyy="1E-12" iyz="0" izz="1E-12" />
      </inertial>
      <collision>
        <geometry>
          <!-- <sphere radius="0.012"/> -->
          <sphere radius="0.02"/>
        </geometry>
      </collision>
    </link>

    <joint name="FL_Ankle" type="fixed">
      <!-- <origin xyz="0 0 -0.19"/> -->
      <origin xyz="0 0 -0.2"/>
      <parent link="FL_SHANK" />
      <child link="FL_FOOT" />
    </joint>


    <link name="FR_HIP">
      <inertial>
        <origin xyz="-0.0047 0.0091 -0.0018" />
        <mass value="0.428" />
        <inertia ixx="0.00014538" ixy="-8.1551E-07" ixz="-1.2639E-05" iyy="0.00024024" iyz="-1.3441E-06" izz="0.00013038" />
      </inertial>
      <visual>
        <geometry>
          <mesh filename="package://lite2_description/meshes/FR_HIP.dae" />
        </geometry>
      </visual>
    </link>

    <joint name="FR_HipX" type="revolute">
      <origin xyz="0.175 -0.055 0" />
      <parent link="TORSO" />
      <child link="FR_HIP" />
      <axis xyz="-1 0 0" />
      <limit lower="-0.523" upper="0.523" effort="13.2" velocity="20" />
    </joint>

    <link name="FR_THIGH">
      <inertial>
        <origin xyz="-0.00523 0.0216 -0.0273" />
        <mass value="0.61" />
        <inertia ixx="0.001" ixy="2.5E-06" ixz="-1.12E-04" iyy="0.00116" iyz="-3.75E-07" izz="2.68E-04" />
      </inertial>
      <visual>
        <origin rpy="1.570796 0 0" xyz="0 0 0"/>
        <geometry>
          <mesh filename="package://lite2_description/meshes/R_THIGH2.dae" />
        </geometry>
      </visual>
      <collision>
        <origin xyz="0 0 -0.08"/>
        <geometry>
          <box size="0.03 0.03 0.16"/>
        </geometry>
      </collision>
    </link>

    <joint name="FR_HipY" type="revolute">
      <origin xyz="0 -0.08 0" />
      <parent link="FR_HIP" />
      <child link="FR_THIGH" />
      <axis xyz="0 -1 0" />
      <limit lower="-3.49" upper="0.349" effort="13.2" velocity="20" />
    </joint>

    <link name="FR_SHANK">
      <inertial>
        <origin xyz="0.00585 -8.732E-07 -0.12" />
        <mass value="0.145" />
        <inertia ixx="6.68E-04" ixy="-1.24E-08" ixz="6.91E-06" iyy="6.86E-04" iyz="5.65E-09" izz="3.155E-05" />
      </inertial>
      <visual>
        <geometry>
          <mesh filename="package://lite2_description/meshes/SHANK.dae" />
        </geometry>
      </visual>
      <collision>
        <!-- <origin xyz="0 0 -0.08"/> -->
        <origin xyz="0 0 -0.09"/>
        <geometry>
          <!-- <box size="0.02 0.02 0.16"/> -->
          <box size="0.02 0.02 0.18"/>
        </geometry>
      </collision>
    </link>

    <joint name="FR_Knee" type="revolute">
      <origin xyz="0 0 -0.18" />
      <parent link="FR_THIGH" />
      <child link="FR_SHANK" />
      <axis xyz="0 -1 0" />
      <limit lower="0.419" upper="2.53" effort="28" velocity="20" />
    </joint>

    <link name="FR_FOOT">
      <inertial>
        <mass value="1E-12" />
        <inertia ixx="1E-12" ixy="0" ixz="0" iyy="1E-12" iyz="0" izz="1E-12" />
      </inertial>
      <collision>
        <geometry>
          <!-- <sphere radius="0.012"/> -->
          <sphere radius="0.02"/>
        </geometry>
      </collision>
    </link>

    <joint name="FR_Ankle" type="fixed">
      <!-- <origin xyz="0 0 -0.19"/> -->
      <origin xyz="0 0 -0.2"/>
      <parent link="FR_SHANK" />
      <child link="FR_FOOT" />
    </joint>



    <link name="HL_HIP">
      <inertial>
        <origin xyz="0.0047 -0.0091 -0.0018" />
        <mass value="0.428" />
        <inertia ixx="0.00014538" ixy="-8.1585E-07" ixz="1.2639E-05" iyy="0.00024024" iyz="1.3444E-06" izz="0.00013038" />
      </inertial>
      <visual>
        <geometry>
          <mesh filename="package://lite2_description/meshes/HL_HIP.dae" />
        </geometry>
      </visual>
    </link>

    <joint name="HL_HipX" type="revolute">
      <origin xyz="-0.175 0.055 0" />
      <parent link="TORSO" />
      <child link="HL_HIP" />
      <axis xyz="1 0 0" />
      <limit lower="-0.523" upper="0.523" effort="13.2" velocity="20" />
    </joint>

    <link name="HL_THIGH">
      <inertial>
        <origin xyz="-0.00523 -0.0216 -0.0273" />
        <mass value="0.61" />
        <inertia ixx="0.001" ixy="-2.5E-06" ixz="-1.12E-04" iyy="0.00116" iyz="3.75E-07" izz="2.68E-04" />
      </inertial>
      <visual>
        <geometry>
          <mesh filename="package://lite2_description/meshes/L_THIGH.dae" />
        </geometry>
      </visual>
      <collision>
        <origin xyz="0 0 -0.06"/>
        <geometry>
          <box size="0.03 0.03 0.12"/>
        </geometry>
      </collision>
    </link>

    <joint name="HL_HipY" type="revolute">
      <origin xyz="0 0.081 0" />
      <parent link="HL_HIP" />
      <child link="HL_THIGH" />
      <axis xyz="0 -1 0" />
      <limit lower="-3.49" upper="0.349" effort="13.2" velocity="20" />
    </joint>

    <link name="HL_SHANK">
      <inertial>
        <origin xyz="0.00585 -8.732E-07 -0.12" />
        <mass value="0.145" />
        <inertia ixx="6.68E-04" ixy="-1.24E-08" ixz="6.91E-06" iyy="6.86E-04" iyz="5.65E-09" izz="3.155E-05" />
      </inertial>
      <visual>
        <geometry>
          <mesh filename="package://lite2_description/meshes/SHANK.dae" />
        </geometry>
      </visual>
      <collision>
        <!-- <origin xyz="0 0 -0.08"/> -->
        <origin xyz="0 0 -0.09"/>
        <geometry>
          <!-- <box size="0.02 0.02 0.16"/> -->
          <box size="0.02 0.02 0.18"/>
        </geometry>
      </collision>
    </link>

    <joint name="HL_Knee" type="revolute">
      <origin xyz="0 0 -0.18" />
      <parent link="HL_THIGH" />
      <child link="HL_SHANK" />
      <axis xyz="0 -1 0" />
      <limit lower="0.419" upper="2.53" effort="28" velocity="20" />
    </joint>

    <link name="HL_FOOT">
      <inertial>
        <mass value="1E-12" />
        <inertia ixx="1E-12" ixy="0" ixz="0" iyy="1E-12" iyz="0" izz="1E-12" />
      </inertial>
      <collision>
        <geometry>
          <!-- <sphere radius="0.012"/> -->
          <sphere radius="0.02"/>
        </geometry>
      </collision>
    </link>

    <joint name="HL_Ankle" type="fixed">
      <!-- <origin xyz="0 0 -0.19"/> -->
      <origin xyz="0 0 -0.2"/>
      <parent link="HL_SHANK" />
      <child link="HL_FOOT" />
    </joint>



    <link name="HR_HIP">
      <inertial>
        <origin xyz="0.0047 0.0091 -0.0018" />
        <mass value="0.428" />
        <inertia ixx="0.00014538" ixy="8.1545E-07" ixz="1.2639E-05" iyy="0.00024024" iyz="-1.344E-06" izz="0.00013038" />
      </inertial>
      <visual>
        <geometry>
          <mesh filename="package://lite2_description/meshes/HR_HIP.dae" />
        </geometry>
      </visual>
    </link>

    <joint name="HR_HipX" type="revolute">
      <origin xyz="-0.175 -0.055 0" />
      <parent link="TORSO" />
      <child link="HR_HIP" />
      <axis xyz="-1 0 0" />
      <limit lower="-0.523" upper="0.523" effort="13.2" velocity="20" />
    </joint>

    <link name="HR_THIGH">
      <inertial>
        <origin xyz="-0.00523 0.0216 -0.0273" />
        <mass value="0.61" />
        <inertia ixx="0.001" ixy="2.5E-06" ixz="-1.12E-04" iyy="0.00116" iyz="-3.75E-07" izz="2.68E-04" />
      </inertial>
      <visual>
        <origin rpy="1.570796 0 0" xyz="0 0 0"/>
        <geometry>
          <mesh filename="package://lite2_description/meshes/R_THIGH2.dae" />
        </geometry>
      </visual>
      <collision>
        <origin xyz="0 0 -0.06"/>
        <geometry>
          <box size="0.03 0.03 0.12"/>
        </geometry>
      </collision>
    </link>

    <joint name="HR_HipY" type="revolute">
      <origin xyz="0 -0.081 0" />
      <parent link="HR_HIP" />
      <child link="HR_THIGH" />
      <axis xyz="0 -1 0" />
      <limit lower="-3.49" upper="0.349" effort="13.2" velocity="20" />
    </joint>

    <link name="HR_SHANK">
      <inertial>
        <origin xyz="0.00585 -8.732E-07 -0.12" />
        <mass value="0.145" />
        <inertia ixx="6.68E-04" ixy="-1.24E-08" ixz="6.91E-06" iyy="6.86E-04" iyz="5.65E-09" izz="3.155E-05" />
      </inertial>
      <visual>
        <geometry>
          <mesh filename="package://lite2_description/meshes/SHANK.dae" />
        </geometry>
      </visual>
      <collision>
        <!-- <origin xyz="0 0 -0.08"/> -->
        <origin xyz="0 0 -0.09"/>
        <geometry>
          <!-- <box size="0.02 0.02 0.16"/> -->
          <box size="0.02 0.02 0.18"/>
        </geometry>
      </collision>
    </link>

    <joint name="HR_Knee" type="revolute">
      <origin xyz="0 0 -0.18" />
      <parent link="HR_THIGH" />
      <child link="HR_SHANK" />
      <axis xyz="0 -1 0" />
      <limit lower="0.419" upper="2.53" effort="28" velocity="20" />
    </joint>

    <link name="HR_FOOT">
      <inertial>
        <mass value="1E-12" />
        <inertia ixx="1E-12" ixy="0" ixz="0" iyy="1E-12" iyz="0" izz="1E-12" />
      </inertial>
      <collision>
        <geometry>
          <!-- <sphere radius="0.012"/> -->
          <sphere radius="0.02"/>
        </geometry>
      </collision>
    </link>

    <joint name="HR_Ankle" type="fixed">
      <!-- <origin xyz="0 0 -0.19"/> -->
      <origin xyz="0 0 -0.2"/>
      <parent link="HR_SHANK" />
      <child link="HR_FOOT" />
    </joint>

</robot>
