<?xml version="1.0" encoding="utf-8"?>
<robot name="MiniLiteV2">
  <link name="TORSO">
    <visual>
      <geometry>
        <mesh filename="package://robot_function_pkg/meshes/meshes/TORSO.dae" />
      </geometry>
    </visual>
    <collision>
      <geometry>
        <box size="0.234 0.184 0.08"/>
      </geometry>
    </collision>
  </link>

  <link name="INERTIA">
    <inertial>
      <origin xyz="0.046396 -0.0017592 0.028665" />
      <mass value="5.298" />
      <inertia ixx="0.0095569" ixy="5.9672E-05" ixz="9.3193E-05" iyy="0.014357" iyz="1.9063E-05" izz="0.01949" />
    </inertial>
  </link>

  <joint name="Torso2Inertia" type="fixed">
    <parent link="TORSO" />
    <child link="INERTIA" />
  </joint>

  <link name="FL_HIP">
    <inertial>
      <origin xyz="-0.0047 -0.0091 -0.0018" />
      <mass value="0.428" />
      <inertia ixx="0.00014538" ixy="8.1579E-07" ixz="-1.264E-05" iyy="0.00024024" iyz="1.3443E-06" izz="0.00013038" />
    </inertial>
    <visual>
      <geometry>
       <mesh filename="package://robot_function_pkg/meshes/meshes/FL_HIP.dae" />
      </geometry>
    </visual>
  </link>

  <joint name="FL_HipX" type="revolute">
    <origin xyz="0.175 0.055 0" />
    <parent link="TORSO" />
    <child link="FL_HIP" />
    <axis xyz="1 0 0" />
    <limit lower="-0.523" upper="0.523" effort="13.2" velocity="20" />
  </joint>

  <link name="FL_THIGH">
    <inertial>
      <origin xyz="-0.00523 -0.0216 -0.0273" />
      <mass value="0.61" />
      <inertia ixx="0.001" ixy="-2.5E-06" ixz="-1.12E-04" iyy="0.00116" iyz="3.75E-07" izz="2.68E-04" />
    </inertial>
    <visual>
      <geometry>
        <mesh filename="package://robot_function_pkg/meshes/meshes/L_THIGH.dae" />
      </geometry>
    </visual>
    <collision>
      <origin xyz="0 0 -0.06"/>
      <geometry>
        <box size="0.04 0.03 0.12"/>
      </geometry>
    </collision>
  </link>

  <joint name="FL_HipY" type="revolute">
    <origin xyz="0 0.081 0" />
    <parent link="FL_HIP" />
    <child link="FL_THIGH" />
    <axis xyz="0 -1 0" />
    <limit lower="-3.49" upper="0.349" effort="13.2" velocity="20" />
  </joint>

  <link name="FL_SHANK">
    <inertial>
      <origin xyz="0.00585 -8.732E-07 -0.12" />
      <mass value="0.145" />
      <inertia ixx="6.68E-04" ixy="-1.24E-08" ixz="6.91E-06" iyy="6.86E-04" iyz="5.65E-09" izz="3.155E-05" />
    </inertial>
    <visual>
      <geometry>
        <mesh filename="package://robot_function_pkg/meshes/meshes/SHANK.dae" />
      </geometry>
    </visual>
    <collision>
      <geometry>
        <mesh filename="package://robot_function_pkg/meshes/meshes/SHANK.obj" />
      </geometry>
    </collision>
  </link>

  <joint name="FL_Knee" type="revolute">
    <origin xyz="0 0 -0.18" />
    <parent link="FL_THIGH" />
    <child link="FL_SHANK" />
    <axis xyz="0 -1 0" />
    <limit lower="0.419" upper="2.53" effort="28" velocity="20" />
  </joint>

  <transmission name="FL_HipX_tran">
    <type>transmission_interface/SimpleTransmission</type>
    <joint name="FL_HipX">
      <hardwareInterface>hardware_interface/EffortJointInterface</hardwareInterface>
    </joint>
    <actuator name="FL_HipX_motor">
      <mechanicalReduction>1</mechanicalReduction>
    </actuator>
  </transmission>

  <transmission name="FL_HipY_tran">
    <type>transmission_interface/SimpleTransmission</type>
    <joint name="FL_HipY">
      <hardwareInterface>hardware_interface/EffortJointInterface</hardwareInterface>
    </joint>
    <actuator name="FL_HipY_motor">
      <mechanicalReduction>1</mechanicalReduction>
    </actuator>
  </transmission>

  <transmission name="FL_Knee_tran">
    <type>transmission_interface/SimpleTransmission</type>
    <joint name="FL_Knee">
      <hardwareInterface>hardware_interface/EffortJointInterface</hardwareInterface>
    </joint>
    <actuator name="FL_Knee_motor">
      <mechanicalReduction>1</mechanicalReduction>
    </actuator>
  </transmission>

  <link name="FR_HIP">
    <inertial>
      <origin xyz="-0.0047 0.0091 -0.0018" />
      <mass value="0.428" />
      <inertia ixx="0.00014538" ixy="-8.1551E-07" ixz="-1.2639E-05" iyy="0.00024024" iyz="-1.3441E-06" izz="0.00013038" />
    </inertial>
    <visual>
      <geometry>
        <mesh filename="package://robot_function_pkg/meshes/meshes/FR_HIP.dae" />
      </geometry>
    </visual>
  </link>

  <joint name="FR_HipX" type="revolute">
    <origin xyz="0.175 -0.055 0" />
    <parent link="TORSO" />
    <child link="FR_HIP" />
    <axis xyz="-1 0 0" />
    <limit lower="-0.523" upper="0.523" effort="13.2" velocity="20" />
  </joint>

  <link name="FR_THIGH">
    <inertial>
      <origin xyz="-0.00523 0.0216 -0.0273" />
      <mass value="0.61" />
      <inertia ixx="0.001" ixy="2.5E-06" ixz="-1.12E-04" iyy="0.00116" iyz="-3.75E-07" izz="2.68E-04" />
    </inertial>
    <visual>
      <origin rpy="0 0 0" xyz="0 0 0"/>
      <geometry>
        <mesh filename="package://robot_function_pkg/meshes/meshes/R_THIGH.dae" />
      </geometry>
    </visual>
    <collision>
      <origin xyz="0 0 -0.06"/>
      <geometry>
        <box size="0.04 0.03 0.12"/>
      </geometry>
    </collision>
  </link>

  <joint name="FR_HipY" type="revolute">
    <origin xyz="0 -0.08 0" />
    <parent link="FR_HIP" />
    <child link="FR_THIGH" />
    <axis xyz="0 -1 0" />
    <limit lower="-3.49" upper="0.349" effort="13.2" velocity="20" />
  </joint>

  <link name="FR_SHANK">
    <inertial>
      <origin xyz="0.00585 -8.732E-07 -0.12" />
      <mass value="0.145" />
      <inertia ixx="6.68E-04" ixy="-1.24E-08" ixz="6.91E-06" iyy="6.86E-04" iyz="5.65E-09" izz="3.155E-05" />
    </inertial>
    <visual>
      <geometry>
        <mesh filename="package://robot_function_pkg/meshes/meshes/SHANK.dae" />
      </geometry>
    </visual>
    <collision>
      <geometry>
        <mesh filename="package://robot_function_pkg/meshes/meshes/SHANK.obj" />
      </geometry>
    </collision>
  </link>

  <joint name="FR_Knee" type="revolute">
    <origin xyz="0 0 -0.18" />
    <parent link="FR_THIGH" />
    <child link="FR_SHANK" />
    <axis xyz="0 -1 0" />
    <limit lower="0.419" upper="2.53" effort="28" velocity="20" />
  </joint>

  <transmission name="FR_HipX_tran">
    <type>transmission_interface/SimpleTransmission</type>
    <joint name="FR_HipX">
      <hardwareInterface>hardware_interface/EffortJointInterface</hardwareInterface>
    </joint>
    <actuator name="FR_HipX_motor">
      <mechanicalReduction>1</mechanicalReduction>
    </actuator>
  </transmission>

  <transmission name="FR_HipY_tran">
    <type>transmission_interface/SimpleTransmission</type>
    <joint name="FR_HipY">
      <hardwareInterface>hardware_interface/EffortJointInterface</hardwareInterface>
    </joint>
    <actuator name="FR_HipY_motor">
      <mechanicalReduction>1</mechanicalReduction>
    </actuator>
  </transmission>

  <transmission name="FR_Knee_tran">
    <type>transmission_interface/SimpleTransmission</type>
    <joint name="FR_Knee">
      <hardwareInterface>hardware_interface/EffortJointInterface</hardwareInterface>
    </joint>
    <actuator name="FR_Knee_motor">
      <mechanicalReduction>1</mechanicalReduction>
    </actuator>
  </transmission>

  <link name="HL_HIP">
    <inertial>
      <origin xyz="0.0047 -0.0091 -0.0018" />
      <mass value="0.428" />
      <inertia ixx="0.00014538" ixy="-8.1585E-07" ixz="1.2639E-05" iyy="0.00024024" iyz="1.3444E-06" izz="0.00013038" />
    </inertial>
    <visual>
      <geometry>
        <mesh filename="package://robot_function_pkg/meshes/meshes/HL_HIP.dae" />
      </geometry>
    </visual>
  </link>

  <joint name="HL_HipX" type="revolute">
    <origin xyz="-0.175 0.055 0" />
    <parent link="TORSO" />
    <child link="HL_HIP" />
    <axis xyz="1 0 0" />
    <limit lower="-0.523" upper="0.523" effort="13.2" velocity="20" />
  </joint>

  <link name="HL_THIGH">
    <inertial>
      <origin xyz="-0.00523 -0.0216 -0.0273" />
      <mass value="0.61" />
      <inertia ixx="0.001" ixy="-2.5E-06" ixz="-1.12E-04" iyy="0.00116" iyz="3.75E-07" izz="2.68E-04" />
    </inertial>
    <visual>
      <geometry>
        <mesh filename="package://robot_function_pkg/meshes/meshes/L_THIGH.dae" />
      </geometry>
    </visual>
    <collision>
      <origin xyz="0 0 -0.06"/>
      <geometry>
        <box size="0.04 0.03 0.12"/>
      </geometry>
    </collision>
  </link>

  <joint name="HL_HipY" type="revolute">
    <origin xyz="0 0.081 0" />
    <parent link="HL_HIP" />
    <child link="HL_THIGH" />
    <axis xyz="0 -1 0" />
    <limit lower="-3.49" upper="0.349" effort="13.2" velocity="20" />
  </joint>

  <link name="HL_SHANK">
    <inertial>
      <origin xyz="0.00585 -8.732E-07 -0.12" />
      <mass value="0.145" />
      <inertia ixx="6.68E-04" ixy="-1.24E-08" ixz="6.91E-06" iyy="6.86E-04" iyz="5.65E-09" izz="3.155E-05" />
    </inertial>
    <visual>
      <geometry>
        <mesh filename="package://robot_function_pkg/meshes/meshes/SHANK.dae" />
      </geometry>
    </visual>
    <collision>
      <geometry>
        <mesh filename="package://robot_function_pkg/meshes/meshes/SHANK.obj" />
      </geometry>
    </collision>
  </link>

  <joint name="HL_Knee" type="revolute">
    <origin xyz="0 0 -0.18" />
    <parent link="HL_THIGH" />
    <child link="HL_SHANK" />
    <axis xyz="0 -1 0" />
    <limit lower="0.419" upper="2.53" effort="28" velocity="20" />
  </joint>

  <transmission name="HL_HipX_tran">
    <type>transmission_interface/SimpleTransmission</type>
    <joint name="HL_HipX">
      <hardwareInterface>hardware_interface/EffortJointInterface</hardwareInterface>
    </joint>
    <actuator name="HL_HipX_motor">
      <mechanicalReduction>1</mechanicalReduction>
    </actuator>
  </transmission>

  <transmission name="HL_HipY_tran">
    <type>transmission_interface/SimpleTransmission</type>
    <joint name="HL_HipY">
      <hardwareInterface>hardware_interface/EffortJointInterface</hardwareInterface>
    </joint>
    <actuator name="HL_HipY_motor">
      <mechanicalReduction>1</mechanicalReduction>
    </actuator>
  </transmission>

  <transmission name="HL_Knee_tran">
    <type>transmission_interface/SimpleTransmission</type>
    <joint name="HL_Knee">
      <hardwareInterface>hardware_interface/EffortJointInterface</hardwareInterface>
    </joint>
    <actuator name="HL_Knee_motor">
      <mechanicalReduction>1</mechanicalReduction>
    </actuator>
  </transmission>

  <link name="HR_HIP">
    <inertial>
      <origin xyz="0.0047 0.0091 -0.0018" />
      <mass value="0.428" />
      <inertia ixx="0.00014538" ixy="8.1545E-07" ixz="1.2639E-05" iyy="0.00024024" iyz="-1.344E-06" izz="0.00013038" />
    </inertial>
    <visual>
      <geometry>
        <mesh filename="package://robot_function_pkg/meshes/meshes/HR_HIP.dae" />
      </geometry>
    </visual>
  </link>

  <joint name="HR_HipX" type="revolute">
    <origin xyz="-0.175 -0.055 0" />
    <parent link="TORSO" />
    <child link="HR_HIP" />
    <axis xyz="-1 0 0" />
    <limit lower="-0.523" upper="0.523" effort="13.2" velocity="20" />
  </joint>

  <link name="HR_THIGH">
    <inertial>
      <origin xyz="-0.00523 0.0216 -0.0273" />
      <mass value="0.61" />
      <inertia ixx="0.001" ixy="2.5E-06" ixz="-1.12E-04" iyy="0.00116" iyz="-3.75E-07" izz="2.68E-04" />
    </inertial>
    <visual>
      <origin rpy="0 0 0" xyz="0 0 0"/>
      <geometry>
        <mesh filename="package://robot_function_pkg/meshes/meshes/R_THIGH.dae" />
      </geometry>
    </visual>
    <collision>
      <origin xyz="0 0 -0.06"/>
      <geometry>
        <box size="0.04 0.03 0.12"/>
      </geometry>
    </collision>
  </link>

  <joint name="HR_HipY" type="revolute">
    <origin xyz="0 -0.081 0" />
    <parent link="HR_HIP" />
    <child link="HR_THIGH" />
    <axis xyz="0 -1 0" />
    <limit lower="-3.49" upper="0.349" effort="13.2" velocity="20" />
  </joint>

  <link name="HR_SHANK">
    <inertial>
      <origin xyz="0.00585 -8.732E-07 -0.12" />
      <mass value="0.145" />
      <inertia ixx="6.68E-04" ixy="-1.24E-08" ixz="6.91E-06" iyy="6.86E-04" iyz="5.65E-09" izz="3.155E-05" />
    </inertial>
    <visual>
      <geometry>
        <mesh filename="package://robot_function_pkg/meshes/meshes/SHANK.dae" />
      </geometry>
    </visual>
    <collision>
      <geometry>
        <mesh filename="package://robot_function_pkg/meshes/meshes/SHANK.obj" />
      </geometry>
    </collision>
  </link>

  <joint name="HR_Knee" type="revolute">
    <origin xyz="0 0 -0.18" />
    <parent link="HR_THIGH" />
    <child link="HR_SHANK" />
    <axis xyz="0 -1 0" />
    <limit lower="0.419" upper="2.53" effort="28" velocity="20" />
  </joint>

  <transmission name="HR_HipX_tran">
    <type>transmission_interface/SimpleTransmission</type>
    <joint name="HR_HipX">
      <hardwareInterface>hardware_interface/EffortJointInterface</hardwareInterface>
    </joint>
    <actuator name="HR_HipX_motor">
      <mechanicalReduction>1</mechanicalReduction>
    </actuator>
  </transmission>

  <transmission name="HR_HipY_tran">
    <type>transmission_interface/SimpleTransmission</type>
    <joint name="HR_HipY">
      <hardwareInterface>hardware_interface/EffortJointInterface</hardwareInterface>
    </joint>
    <actuator name="HR_HipY_motor">
      <mechanicalReduction>1</mechanicalReduction>
    </actuator>
  </transmission>

  <transmission name="HR_Knee_tran">
    <type>transmission_interface/SimpleTransmission</type>
    <joint name="HR_Knee">
      <hardwareInterface>hardware_interface/EffortJointInterface</hardwareInterface>
    </joint>
    <actuator name="HR_Knee_motor">
      <mechanicalReduction>1</mechanicalReduction>
    </actuator>
  </transmission>

</robot>
