<?xml version="1.0" encoding="utf-8"?>
<robot name="MiniLiteV2">
  <gazebo>
    <plugin filename="libgazebo_ros_control.so" name="gazebo_ros_control">
      <robotNamespace>/lite2_gazebo</robotNamespace>
      <robotSimType>gazebo_ros_control/DefaultRobotHWSim</robotSimType>
    </plugin>
  </gazebo>
  <gazebo reference="imu_link">
    <gravity>true</gravity>
    <sensor name="imu_sensor" type="imu">
      <always_on>true</always_on>
      <update_rate>1000</update_rate>
      <visualize>true</visualize>
      <topic>__default_topic__</topic>
      <plugin filename="libgazebo_ros_imu_sensor.so" name="imu_plugin">
        <topicName>trunk_imu</topicName>
        <bodyName>imu_link</bodyName>
        <updateRateHZ>1000.0</updateRateHZ>
        <gaussianNoise>0.0</gaussianNoise>
        <xyzOffset>0 0 0</xyzOffset>
        <rpyOffset>0 0 0</rpyOffset>
        <frameName>imu_link</frameName>
      </plugin>
      <pose>0 0 0 0 0 0</pose>
    </sensor>
  </gazebo>
  <!-- Foot contacts. -->
  <gazebo reference="FR_SHANK">
    <sensor name="FR_foot_contact" type="contact">
      <update_rate>100</update_rate>
      <plugin filename="libunitreeFootContactPlugin.so" name="contactPlugin"/>
      <contact>
        <collision>FR_calf_fixed_joint_lump__FR_foot_collision_1</collision>
      </contact>
    </sensor>
  </gazebo>
    <gazebo reference="FL_SHANK">
    <sensor name="FL_foot_contact" type="contact">
      <update_rate>100</update_rate>
      <plugin filename="libunitreeFootContactPlugin.so" name="contactPlugin"/>
      <contact>
        <collision>FL_calf_fixed_joint_lump__FR_foot_collision_1</collision>
      </contact>
    </sensor>
  </gazebo>
    <gazebo reference="HR_SHANK">
    <sensor name="HR_foot_contact" type="contact">
      <update_rate>100</update_rate>
      <plugin filename="libunitreeFootContactPlugin.so" name="contactPlugin"/>
      <contact>
        <collision>HR_calf_fixed_joint_lump__FR_foot_collision_1</collision>
      </contact>
    </sensor>
  </gazebo>
    <gazebo reference="HL_SHANK">
    <sensor name="HL_foot_contact" type="contact">
      <update_rate>100</update_rate>
      <plugin filename="libunitreeFootContactPlugin.so" name="contactPlugin"/>
      <contact>
        <collision>HL_calf_fixed_joint_lump__FR_foot_collision_1</collision>
      </contact>
    </sensor>
  </gazebo>
  <gazebo reference="TORSO">
    <mu1>0.2</mu1>
    <mu2>0.2</mu2>
    <kp value="1000000.0"/>
    <kd value="1.0"/>
  </gazebo>
  <gazebo reference="FL_HIP">
    <mu1>0.2</mu1>
    <mu2>0.2</mu2>
  </gazebo>
  <gazebo reference="FL_THIGH">
    <mu1>0.2</mu1>
    <mu2>0.2</mu2>
    <self_collide>1</self_collide>
    <kp value="1000000.0"/>
    <kd value="1.0"/>
  </gazebo>
  <gazebo reference="FL_SHANK">
    <mu1>0.2</mu1>
    <mu2>0.2</mu2>
    <self_collide>1</self_collide>
  </gazebo>
  <gazebo reference="FL_FOOT">
    <mu1>0.6</mu1>
    <mu2>0.6</mu2>
    <self_collide>1</self_collide>
    <kp value="1000000.0"/>
    <kd value="1.0"/>
  </gazebo>

    <gazebo reference="FR_HIP">
    <mu1>0.2</mu1>
    <mu2>0.2</mu2>
  </gazebo>
  <gazebo reference="FR_THIGH">
    <mu1>0.2</mu1>
    <mu2>0.2</mu2>
    <self_collide>1</self_collide>
    <kp value="1000000.0"/>
    <kd value="1.0"/>
  </gazebo>
  <gazebo reference="FR_SHANK">
    <mu1>0.2</mu1>
    <mu2>0.2</mu2>
    <self_collide>1</self_collide>
  </gazebo>
  <gazebo reference="FR_FOOT">
    <mu1>0.6</mu1>
    <mu2>0.6</mu2>
    <self_collide>1</self_collide>
    <kp value="1000000.0"/>
    <kd value="1.0"/>
  </gazebo>

    <gazebo reference="HL_HIP">
    <mu1>0.2</mu1>
    <mu2>0.2</mu2>
  </gazebo>
  <gazebo reference="HL_THIGH">
    <mu1>0.2</mu1>
    <mu2>0.2</mu2>
    <self_collide>1</self_collide>
    <kp value="1000000.0"/>
    <kd value="1.0"/>
  </gazebo>
  <gazebo reference="HL_SHANK">
    <mu1>0.2</mu1>
    <mu2>0.2</mu2>
    <self_collide>1</self_collide>
  </gazebo>
  <gazebo reference="HL_FOOT">
    <mu1>0.6</mu1>
    <mu2>0.6</mu2>
    <self_collide>1</self_collide>
    <kp value="1000000.0"/>
    <kd value="1.0"/>
  </gazebo>

    <gazebo reference="HR_HIP">
    <mu1>0.2</mu1>
    <mu2>0.2</mu2>
  </gazebo>
  <gazebo reference="HR_THIGH">
    <mu1>0.2</mu1>
    <mu2>0.2</mu2>
    <self_collide>1</self_collide>
    <kp value="1000000.0"/>
    <kd value="1.0"/>
  </gazebo>
  <gazebo reference="HR_SHANK">
    <mu1>0.2</mu1>
    <mu2>0.2</mu2>
    <self_collide>1</self_collide>
  </gazebo>
  <gazebo reference="HR_FOOT">
    <mu1>0.6</mu1>
    <mu2>0.6</mu2>
    <self_collide>1</self_collide>
    <kp value="1000000.0"/>
    <kd value="1.0"/>
  </gazebo>
  <gazebo reference="imu_link">
    <mu1>0.2</mu1>
    <mu2>0.2</mu2>
    <material>Gazebo/Red</material>
  </gazebo>
<link name="TORSO">
    <visual>
      <origin rpy="-1.570796 3.1415926 3.1415926" xyz="0 0 0"/>
      <geometry>
        <mesh filename="package://lite2_description/meshes/TORSO2.dae" />
      </geometry>
    </visual>
    <collision>
      <geometry>
        <box size="0.234 0.184 0.08"/>
      </geometry>
    </collision>
  </link>
  <joint name="Torso2Inertia" type="fixed">
    <parent link="TORSO" />
    <child link="INERTIA" />
  </joint>
<link name="INERTIA">
    <inertial>
      <origin xyz="0.046396 -0.0017592 0.028665" />
      <mass value="5.298" />
      <inertia ixx="0.0095569" ixy="5.9672E-05" ixz="9.3193E-05" iyy="0.014357" iyz="1.9063E-05" izz="0.01949" />
    </inertial>
  </link>
    <joint name="imu_joint" type="fixed">
    <parent link="TORSO"/>
    <child link="imu_link"/>
    <origin rpy="0 0 0" xyz="0 0 0"/>
  </joint>
  <link name="imu_link">
    <inertial>
      <mass value="0.001"/>
      <origin rpy="0 0 0" xyz="0 0 0"/>
      <inertia ixx="0.0001" ixy="0" ixz="0" iyy="0.0001" iyz="0" izz="0.0001"/>
    </inertial>
    <visual>
      <origin rpy="0 0 0" xyz="0 0 0"/>
      <geometry>
        <box size="0.001 0.001 0.001"/>
      </geometry>
      <material name="red"/>
    </visual>
    <collision>
      <origin rpy="0 0 0" xyz="0 0 0"/>
      <geometry>
        <box size=".001 .001 .001"/>
      </geometry>
    </collision>
  </link>  
  <link name="FL_HIP">
    <inertial>
      <origin xyz="-0.0047 -0.0091 -0.0018" />
      <mass value="0.428" />
      <inertia ixx="0.00014538" ixy="8.1579E-07" ixz="-1.264E-05" iyy="0.00024024" iyz="1.3443E-06" izz="0.00013038" />
    </inertial>
    <visual>
      <geometry>
       <mesh filename="package://lite2_description/meshes/FL_HIP.dae" />
      </geometry>
    </visual>
  </link>

  <joint name="FL_hip_joint" type="revolute">
    <origin xyz="0.175 0.055 0" rpy="0 0 0"/>
    <parent link="TORSO" />
    <child link="FL_HIP" />
    <axis xyz="1 0 0" />
    <limit lower="-0.523" upper="0.523" effort="13.2" velocity="20" />
  </joint>

  <link name="FL_THIGH">
    <inertial>
      <origin xyz="-0.00523 -0.0216 -0.0273" />
      <mass value="0.61" />
      <inertia ixx="0.001" ixy="-2.5E-06" ixz="-1.12E-04" iyy="0.00116" iyz="3.75E-07" izz="2.68E-04" />
    </inertial>
    <visual>
      <geometry>
        <mesh filename="package://lite2_description/meshes/L_THIGH.dae" />
      </geometry>
    </visual>
    <collision>
      <origin xyz="-0.01 0 -0.055" rpy="0 0.3 0"/>
      <geometry>
        <box size="0.03 0.03 0.16"/>
      </geometry>
    </collision>
  </link>

  <joint name="FL_thigh_joint" type="revolute">
    <origin xyz="0 0.081 0"  rpy="0 0 0"/>
    <parent link="FL_HIP" />
    <child link="FL_THIGH" />
    <axis xyz="0 -1 0" />
    <limit lower="-3.49" upper="0.349" effort="13.2" velocity="20" />
  </joint>

  <link name="FL_SHANK">
    <inertial>
      <origin xyz="0.00585 -8.732E-07 -0.12" />
      <mass value="0.145" />
      <inertia ixx="6.68E-04" ixy="-1.24E-08" ixz="6.91E-06" iyy="6.86E-04" iyz="5.65E-09" izz="3.155E-05" />
    </inertial>
    <visual>
      <geometry>
        <mesh filename="package://lite2_description/meshes/SHANK.dae" />
      </geometry>
    </visual>
    <collision>
      <origin xyz="0 0 -0.08"/>
      <geometry>
        <box size="0.02 0.02 0.16"/>
      </geometry>
    </collision>
  </link>

  <joint name="FL_calf_joint" type="revolute">
    <origin xyz="0 0 -0.18"  rpy="0 0 0"/>
    <parent link="FL_THIGH" />
    <child link="FL_SHANK" />
    <axis xyz="0 -1 0" />
    <limit lower="0.419" upper="2.53" effort="28" velocity="20" />
  </joint>

  <link name="FL_FOOT">
    <inertial>
      <mass value="1E-12" />
      <inertia ixx="1E-12" ixy="0" ixz="0" iyy="1E-12" iyz="0" izz="1E-12" />
    </inertial>
    <collision>
    <origin xyz="0 0 -0.01"/>
      <geometry>
        <sphere radius="0.024"/>
      </geometry>
    </collision>
  </link>

  <joint name="FL_foot_fixed" type="fixed">
    <origin xyz="0 0 -0.19" rpy="0 0 0"/>
    <parent link="FL_SHANK" />
    <child link="FL_FOOT" />
  </joint>

  <transmission name="FL_hip_tran">
    <type>transmission_interface/SimpleTransmission</type>
    <joint name="FL_hip_joint">
      <hardwareInterface>hardware_interface/EffortJointInterface</hardwareInterface>
    </joint>
    <actuator name="FL_hip_motor">
      <mechanicalReduction>1</mechanicalReduction>
    </actuator>
  </transmission>

  <transmission name="FL_thigh_tran">
    <type>transmission_interface/SimpleTransmission</type>
    <joint name="FL_thigh_joint">
      <hardwareInterface>hardware_interface/EffortJointInterface</hardwareInterface>
    </joint>
    <actuator name="FL_thigh_motor">
      <mechanicalReduction>1</mechanicalReduction>
    </actuator>
  </transmission>

  <transmission name="FL_calf_tran">
    <type>transmission_interface/SimpleTransmission</type>
    <joint name="FL_calf_joint">
      <hardwareInterface>hardware_interface/EffortJointInterface</hardwareInterface>
    </joint>
    <actuator name="FL_calf_motor">
      <mechanicalReduction>1</mechanicalReduction>
    </actuator>
  </transmission>

  <link name="FR_HIP">
    <inertial>
      <origin xyz="-0.0047 0.0091 -0.0018" />
      <mass value="0.428" />
      <inertia ixx="0.00014538" ixy="-8.1551E-07" ixz="-1.2639E-05" iyy="0.00024024" iyz="-1.3441E-06" izz="0.00013038" />
    </inertial>
    <visual>
      <geometry>
        <mesh filename="package://lite2_description/meshes/FR_HIP.dae" />
      </geometry>
    </visual>
  </link>

  <joint name="FR_hip_joint" type="revolute">
    <origin xyz="0.175 -0.055 0"  rpy="0 0 0"/>
    <parent link="TORSO" />
    <child link="FR_HIP" />
    <axis xyz="-1 0 0" />
    <limit lower="-0.523" upper="0.523" effort="13.2" velocity="20" />
  </joint>

  <link name="FR_THIGH">
    <inertial>
      <origin xyz="-0.00523 0.0216 -0.0273" />
      <mass value="0.61" />
      <inertia ixx="0.001" ixy="2.5E-06" ixz="-1.12E-04" iyy="0.00116" iyz="-3.75E-07" izz="2.68E-04" />
    </inertial>
    <visual>
      <origin rpy="1.570796 0 0" xyz="0 0 0"/>
      <geometry>
        <mesh filename="package://lite2_description/meshes/R_THIGH2.dae" />
      </geometry>
    </visual>
    <collision>
      <origin xyz="-0.01 0 -0.055" rpy="0 0.3 0"/>
      <geometry>
        <box size="0.03 0.03 0.16"/>
      </geometry>
    </collision>
  </link>

  <joint name="FR_thigh_joint" type="revolute">
    <origin xyz="0 -0.08 0"  rpy="0 0 0"/>
    <parent link="FR_HIP" />
    <child link="FR_THIGH" />
    <axis xyz="0 -1 0" />
    <limit lower="-3.49" upper="0.349" effort="13.2" velocity="20" />
  </joint>

  <link name="FR_SHANK">
    <inertial>
      <origin xyz="0.00585 -8.732E-07 -0.12" />
      <mass value="0.145" />
      <inertia ixx="6.68E-04" ixy="-1.24E-08" ixz="6.91E-06" iyy="6.86E-04" iyz="5.65E-09" izz="3.155E-05" />
    </inertial>
    <visual>
      <geometry>
        <mesh filename="package://lite2_description/meshes/SHANK.dae" />
      </geometry>
    </visual>
    <collision>
      <origin xyz="0 0 -0.08"/>
      <geometry>
        <box size="0.02 0.02 0.16"/>
      </geometry>
    </collision>
  </link>

  <joint name="FR_calf_joint" type="revolute">
    <origin xyz="0 0 -0.18" rpy="0 0 0"/>
    <parent link="FR_THIGH" />
    <child link="FR_SHANK" />
    <axis xyz="0 -1 0" />
    <limit lower="0.419" upper="2.53" effort="28" velocity="20" />
  </joint>

 <link name="FR_FOOT">
    <inertial>
      <mass value="1E-12" />
      <inertia ixx="1E-12" ixy="0" ixz="0" iyy="1E-12" iyz="0" izz="1E-12" />
    </inertial>
    <collision>
    <origin xyz="0 0 -0.01"/>
      <geometry>
        <sphere radius="0.024"/>
      </geometry>
    </collision>
  </link>

  <joint name="FR_foot_fixed" type="fixed">
    <origin xyz="0 0 -0.19" rpy="0 0 0"/>
    <parent link="FR_SHANK" />
    <child link="FR_FOOT" />
  </joint>

   <transmission name="FR_hip_tran">
    <type>transmission_interface/SimpleTransmission</type>
    <joint name="FR_hip_joint">
      <hardwareInterface>hardware_interface/EffortJointInterface</hardwareInterface>
    </joint>
    <actuator name="FR_hip_motor">
      <hardwareInterface>hardware_interface/EffortJointInterface</hardwareInterface>
      <mechanicalReduction>1</mechanicalReduction>
    </actuator>
  </transmission>
  <transmission name="FR_thigh_tran">
    <type>transmission_interface/SimpleTransmission</type>
    <joint name="FR_thigh_joint">
      <hardwareInterface>hardware_interface/EffortJointInterface</hardwareInterface>
    </joint>
    <actuator name="FR_thigh_motor">
      <hardwareInterface>hardware_interface/EffortJointInterface</hardwareInterface>
      <mechanicalReduction>1</mechanicalReduction>
    </actuator>
  </transmission>
  <transmission name="FR_calf_tran">
    <type>transmission_interface/SimpleTransmission</type>
    <joint name="FR_calf_joint">
      <hardwareInterface>hardware_interface/EffortJointInterface</hardwareInterface>
    </joint>
    <actuator name="FR_calf_motor">
      <hardwareInterface>hardware_interface/EffortJointInterface</hardwareInterface>
      <mechanicalReduction>1</mechanicalReduction>
    </actuator>
  </transmission>

  <link name="HL_HIP">
    <inertial>
      <origin xyz="0.0047 -0.0091 -0.0018" />
      <mass value="0.428" />
      <inertia ixx="0.00014538" ixy="-8.1585E-07" ixz="1.2639E-05" iyy="0.00024024" iyz="1.3444E-06" izz="0.00013038" />
    </inertial>
    <visual>
      <geometry>
        <mesh filename="package://lite2_description/meshes/HL_HIP.dae" />
      </geometry>
    </visual>
  </link>

  <joint name="RL_hip_joint" type="revolute">
    <origin xyz="-0.175 0.055 0"  rpy="0 0 0"/>
    <parent link="TORSO" />
    <child link="HL_HIP" />
    <axis xyz="1 0 0" />
    <limit lower="-0.523" upper="0.523" effort="13.2" velocity="20" />
  </joint>

  <link name="HL_THIGH">
    <inertial>
      <origin xyz="-0.00523 -0.0216 -0.0273" />
      <mass value="0.61" />
      <inertia ixx="0.001" ixy="-2.5E-06" ixz="-1.12E-04" iyy="0.00116" iyz="3.75E-07" izz="2.68E-04" />
    </inertial>
    <visual>
      <geometry>
        <mesh filename="package://lite2_description/meshes/L_THIGH.dae" />
      </geometry>
    </visual>
    <collision>
      <origin xyz="-0.01 0 -0.055" rpy="0 0.3 0"/>
      <geometry>
        <box size="0.03 0.03 0.16"/>
      </geometry>
    </collision>
  </link>

  <joint name="RL_thigh_joint" type="revolute">
    <origin xyz="0 0.081 0"  rpy="0 0 0"/>
    <parent link="HL_HIP" />
    <child link="HL_THIGH" />
    <axis xyz="0 -1 0" />
    <limit lower="-3.49" upper="0.349" effort="13.2" velocity="20" />
  </joint>

  <link name="HL_SHANK">
    <inertial>
      <origin xyz="0.00585 -8.732E-07 -0.12" />
      <mass value="0.145" />
      <inertia ixx="6.68E-04" ixy="-1.24E-08" ixz="6.91E-06" iyy="6.86E-04" iyz="5.65E-09" izz="3.155E-05" />
    </inertial>
    <visual>
      <geometry>
        <mesh filename="package://lite2_description/meshes/SHANK.dae" />
      </geometry>
    </visual>
    <collision>
      <origin xyz="0 0 -0.08"/>
      <geometry>
        <box size="0.02 0.02 0.16"/>
      </geometry>
    </collision>
  </link>

  <joint name="RL_calf_joint" type="revolute">
    <origin xyz="0 0 -0.18"  rpy="0 0 0"/>
    <parent link="HL_THIGH" />
    <child link="HL_SHANK" />
    <axis xyz="0 -1 0" />
    <limit lower="0.419" upper="2.53" effort="28" velocity="20" />
  </joint>

 <link name="HL_FOOT">
    <inertial>
      <mass value="1E-12" />
      <inertia ixx="1E-12" ixy="0" ixz="0" iyy="1E-12" iyz="0" izz="1E-12" />
    </inertial>
    <collision>
    <origin xyz="0 0 -0.01"/>
      <geometry>
        <sphere radius="0.024"/>
      </geometry>
    </collision>
  </link>

  <joint name="RL_foot_fixed" type="fixed">
    <origin xyz="0 0 -0.19" rpy="0 0 0"/>
    <parent link="HL_SHANK" />
    <child link="HL_FOOT" />
  </joint>

  <transmission name="RL_hip_tran">
    <type>transmission_interface/SimpleTransmission</type>
    <joint name="RL_hip_joint">
      <hardwareInterface>hardware_interface/EffortJointInterface</hardwareInterface>
    </joint>
    <actuator name="RL_hip_motor">
      <hardwareInterface>hardware_interface/EffortJointInterface</hardwareInterface>
      <mechanicalReduction>1</mechanicalReduction>
    </actuator>
  </transmission>
  <transmission name="RL_thigh_tran">
    <type>transmission_interface/SimpleTransmission</type>
    <joint name="RL_thigh_joint">
      <hardwareInterface>hardware_interface/EffortJointInterface</hardwareInterface>
    </joint>
    <actuator name="RL_thigh_motor">
      <hardwareInterface>hardware_interface/EffortJointInterface</hardwareInterface>
      <mechanicalReduction>1</mechanicalReduction>
    </actuator>
  </transmission>
  <transmission name="RL_calf_tran">
    <type>transmission_interface/SimpleTransmission</type>
    <joint name="RL_calf_joint">
      <hardwareInterface>hardware_interface/EffortJointInterface</hardwareInterface>
    </joint>
    <actuator name="RL_calf_motor">
      <hardwareInterface>hardware_interface/EffortJointInterface</hardwareInterface>
      <mechanicalReduction>1</mechanicalReduction>
    </actuator>
  </transmission>

  <link name="HR_HIP">
    <inertial>
      <origin xyz="0.0047 0.0091 -0.0018" />
      <mass value="0.428" />
      <inertia ixx="0.00014538" ixy="8.1545E-07" ixz="1.2639E-05" iyy="0.00024024" iyz="-1.344E-06" izz="0.00013038" />
    </inertial>
    <visual>
      <geometry>
        <mesh filename="package://lite2_description/meshes/HR_HIP.dae" />
      </geometry>
    </visual>
  </link>

  <joint name="RR_hip_joint" type="revolute">
    <origin xyz="-0.175 -0.055 0"  rpy="0 0 0"/>
    <parent link="TORSO" />
    <child link="HR_HIP" />
    <axis xyz="-1 0 0" />
    <limit lower="-0.523" upper="0.523" effort="13.2" velocity="20" />
  </joint>

  <link name="HR_THIGH">
    <inertial>
      <origin xyz="-0.00523 0.0216 -0.0273" />
      <mass value="0.61" />
      <inertia ixx="0.001" ixy="2.5E-06" ixz="-1.12E-04" iyy="0.00116" iyz="-3.75E-07" izz="2.68E-04" />
    </inertial>
    <visual>
      <origin rpy="1.570796 0 0" xyz="0 0 0"/>
      <geometry>
        <mesh filename="package://lite2_description/meshes/R_THIGH2.dae" />
      </geometry>
    </visual>
    <collision>
      <origin xyz="-0.01 0 -0.055" rpy="0 0.3 0"/>
      <geometry>
        <box size="0.03 0.03 0.16"/>
      </geometry>
    </collision>
  </link>

  <joint name="RR_thigh_joint" type="revolute">
    <origin xyz="0 -0.081 0"  rpy="0 0 0"/>
    <parent link="HR_HIP" />
    <child link="HR_THIGH" />
    <axis xyz="0 -1 0" />
    <limit lower="-3.49" upper="0.349" effort="13.2" velocity="20" />
  </joint>

  <link name="HR_SHANK">
    <inertial>
      <origin xyz="0.00585 -8.732E-07 -0.12" />
      <mass value="0.145" />
      <inertia ixx="6.68E-04" ixy="-1.24E-08" ixz="6.91E-06" iyy="6.86E-04" iyz="5.65E-09" izz="3.155E-05" />
    </inertial>
    <visual>
      <geometry>
        <mesh filename="package://lite2_description/meshes/SHANK.dae" />
      </geometry>
    </visual>
    <collision>
      <origin xyz="0 0 -0.08"/>
      <geometry>
        <box size="0.02 0.02 0.16"/>
      </geometry>
    </collision>
  </link>

  <joint name="RR_calf_joint" type="revolute">
    <origin xyz="0 0 -0.18"  rpy="0 0 0"/>
    <parent link="HR_THIGH" />
    <child link="HR_SHANK" />
    <axis xyz="0 -1 0" />
    <limit lower="0.419" upper="2.53" effort="28" velocity="20" />
  </joint>

 <link name="HR_FOOT">
    <inertial>
      <mass value="1E-12" />
      <inertia ixx="1E-12" ixy="0" ixz="0" iyy="1E-12" iyz="0" izz="1E-12" />
    </inertial>
    <collision>
    <origin xyz="0 0 -0.01"/>
      <geometry>
        <sphere radius="0.024"/>
      </geometry>
    </collision>
  </link>

  <joint name="RR_foot_fixed" type="fixed">
    <origin xyz="0 0 -0.19" rpy="0 0 0"/>
    <parent link="HR_SHANK" />
    <child link="HR_FOOT" />
  </joint>

  <transmission name="RR_hip_tran">
    <type>transmission_interface/SimpleTransmission</type>
    <joint name="RR_hip_joint">
      <hardwareInterface>hardware_interface/EffortJointInterface</hardwareInterface>
    </joint>
    <actuator name="RR_hip_motor">
      <hardwareInterface>hardware_interface/EffortJointInterface</hardwareInterface>
      <mechanicalReduction>1</mechanicalReduction>
    </actuator>
  </transmission>
  <transmission name="RR_thigh_tran">
    <type>transmission_interface/SimpleTransmission</type>
    <joint name="RR_thigh_joint">
      <hardwareInterface>hardware_interface/EffortJointInterface</hardwareInterface>
    </joint>
    <actuator name="RR_thigh_motor">
      <hardwareInterface>hardware_interface/EffortJointInterface</hardwareInterface>
      <mechanicalReduction>1</mechanicalReduction>
    </actuator>
  </transmission>
  <transmission name="RR_calf_tran">
    <type>transmission_interface/SimpleTransmission</type>
    <joint name="RR_calf_joint">
      <hardwareInterface>hardware_interface/EffortJointInterface</hardwareInterface>
    </joint>
    <actuator name="RR_calf_motor">
      <hardwareInterface>hardware_interface/EffortJointInterface</hardwareInterface>
      <mechanicalReduction>1</mechanicalReduction>
    </actuator>
  </transmission>

</robot>
